<?xml version="1.0"?>
<robot xmlns:xacro="http://www.ros.org/wiki/xacro">

    <xacro:include filename="inertial_macros.xacro"/>

    <material name="white">
        <color rgba="1 1 1 1"/>
    </material>

    <material name="orange">
        <color rgba="1 0.3 0.1 1"/>
    </material>

    <material name="blue">
        <color rgba="0.2 0.2 1 1"/>
    </material>

    <material name="black">
        <color rgba="0 0 0 1"/>
    </material>

    <!-- Base Link -->

    <link name="base_link">
        
    </link>

    <!-- BASE_FOOTPRINT LINK -->

    <joint name="base_footprint_joint" type="fixed">
        <parent link="base_link"/>
        <child link="base_footprint"/>
        <origin xyz="0 0 0" rpy="0 0 0"/>
    </joint>

    <link name="base_footprint">
    </link>

    <!-- Chassis -->

    <joint name="chassis_joint" type="fixed">
        <parent link="base_link"/>
        <child link="chassis"/>
        <origin xyz = "-0.0625 0 0"/>
    </joint>

    <link name="chassis">
        <visual>
            <origin xyz="0.13 0 0.03"/>
            <geometry>
                <box size="0.26 0.2 0.06"/>
            </geometry>
            <material name="white"/>
        </visual>
        <collision>
            <origin xyz="0.13 0 0.03"/>
            <geometry>
                <box size="0.26 0.2 0.06"/>
            </geometry>
        </collision>
        <xacro:inertial_box mass="2.0" x="0.26" y="0.2" z="0.06">
            <origin xyz="0.13 0 0.03" rpy="0 0 0"/>
        </xacro:inertial_box>
    </link>

    <gazebo reference="chassis">
        <material>Gazebo/White</material>
    </gazebo>

    <!--LEFT WHEEL -->

    <joint name="left_wheel_joint" type="continuous">
        <parent link="base_link"/>
        <child link="left_wheel"/>
        <origin xyz="0 0.13875 0" rpy="-${pi/2} 0 0"/>
        <axis xyz="0 0 1"/>
    </joint>

    <link name="left_wheel">
        <visual>
            <geometry>
                <cylinder radius="0.0625" length="0.0775"/>
            </geometry>
            <material name="blue"/>
        </visual>
        <collision>
            <geometry>
                <cylinder radius="0.0625" length="0.0775"/>
            </geometry>
        </collision>
        <xacro:inertial_cylinder mass="0.4" length="0.0775" radius="0.0625">
            <origin xyz="0 0 0" rpy="0 0 0"/>
        </xacro:inertial_cylinder>
    </link>

    <gazebo reference="left_wheel">
        <material>Gazebo/Blue</material>
    </gazebo>

    <!--RIGHT WHEEL -->

    <joint name="right_wheel_joint" type="continuous">
        <parent link="base_link"/>
        <child link="right_wheel"/>
        <origin xyz="0 -0.13875 0" rpy="${pi/2} 0 0"/>
        <axis xyz="0 0 -1"/>
    </joint>

    <link name="right_wheel">
        <visual>
            <geometry>
                <cylinder radius="0.0625" length="0.0775"/>
            </geometry>
            <material name="blue"/>
        </visual>
        <collision>
            <geometry>
                <cylinder radius="0.0625" length="0.0775"/>
            </geometry>
        </collision>
        <xacro:inertial_cylinder mass="0.4" length="0.0775" radius="0.0625">
            <origin xyz="0 0 0" rpy="0 0 0"/>
        </xacro:inertial_cylinder>
    </link>

    <gazebo reference="right_wheel">
        <material>Gazebo/Blue</material>
    </gazebo>

    <!-- Left Castor Wheel -->

    <joint name="left_castor_wheel_joint" type="fixed">
        <parent link="chassis"/>
        <child link="left_castor_wheel"/>
        <origin xyz="0.2 0.13875 0" rpy="-${pi/2} 0 0"/>
        <axis xyz="0 0 1"/>
    </joint>

    <link name="left_castor_wheel">
        <visual>
            <geometry>
                <cylinder radius="0.0625" length="0.0775"/>
            </geometry>
            <material name="black"/>
        </visual>
        <collision>
            <geometry>
                <cylinder radius="0.0625" length="0.0775"/>
            </geometry>
        </collision>
        <xacro:inertial_cylinder mass="0.4" length="0.0775" radius="0.0625">
            <origin xyz="0 0 0" rpy="0 0 0"/>
        </xacro:inertial_cylinder>
    </link>

    <gazebo reference="left_castor_wheel">
        <material>Gazebo/Black</material>
        <mu1 value="0.001"/>
        <mu2 value="0.001"/>
    </gazebo>

    <!-- Right Castor Wheel -->

    <joint name="right_castor_wheel_joint" type="fixed">
        <parent link="chassis"/>
        <child link="right_castor_wheel"/>
        <origin xyz="0.2 -0.13875 0" rpy="${pi/2} 0 0"/>
        <axis xyz="0 0 -1"/>
    </joint>

    <link name="right_castor_wheel">
        <visual>
            <geometry>
                <cylinder radius="0.0625" length="0.0775"/>
            </geometry>
            <material name="black"/>
        </visual>
        <collision>
            <geometry>
                <cylinder radius="0.0625" length="0.0775"/>
            </geometry>
        </collision>
        <xacro:inertial_cylinder mass="0.4" length="0.0775" radius="0.0625">
            <origin xyz="0 0 0" rpy="0 0 0"/>
        </xacro:inertial_cylinder>
    </link>

    <gazebo reference="right_castor_wheel">
        <material>Gazebo/Black</material>
        <mu1 value="0.001"/>
        <mu2 value="0.001"/>
    </gazebo>

</robot>